2021-12-28 21:15:23,380: DEBUG: found:./autorun_manager
2021-12-28 21:15:23,385: DEBUG: this file/folder is autorun_manager
2021-12-28 21:15:23,385: DEBUG: found:./auto_bt_check
2021-12-28 21:15:23,386: DEBUG:     this is APP
2021-12-28 21:15:23,393: INFO:     [auto_bt_check/settings.py]APP_FOR_AUTO_RUN = True, RUN_FREQUENCY = 1
2021-12-28 21:15:23,394: DEBUG: found:./auto_mail_check
2021-12-28 21:15:23,394: DEBUG:     this is APP
2021-12-28 21:15:23,410: INFO:     [auto_mail_check/settings.py]APP_FOR_AUTO_RUN = True, RUN_FREQUENCY = 10
2021-12-28 21:15:23,410: DEBUG: found:./auto_manga_check
2021-12-28 21:15:23,411: DEBUG: this folder has NOT app.py or settings.py
2021-12-28 21:15:23,411: DEBUG: found:./check.html
2021-12-28 21:15:23,411: DEBUG: this file/folder has "."
2021-12-28 21:15:23,411: DEBUG: found:./config.py
2021-12-28 21:15:23,411: DEBUG: this file/folder has "."
2021-12-28 21:15:23,412: DEBUG: found:./data
2021-12-28 21:15:23,412: DEBUG: this folder has NOT app.py or settings.py
2021-12-28 21:15:23,412: DEBUG: found:./flask_platform
2021-12-28 21:15:23,412: DEBUG:     this is APP
2021-12-28 21:15:23,416: DEBUG: found:./for_offline
2021-12-28 21:15:23,416: DEBUG: this folder has NOT app.py or settings.py
2021-12-28 21:15:23,416: DEBUG: found:./manage.py
2021-12-28 21:15:23,416: DEBUG: this file/folder has "."
2021-12-28 21:15:23,416: DEBUG: found:./modules
2021-12-28 21:15:23,417: DEBUG: this folder has NOT app.py or settings.py
2021-12-28 21:15:23,417: DEBUG: found:./Procfile
2021-12-28 21:15:23,417: DEBUG: this is NOT folder
2021-12-28 21:15:23,417: DEBUG: found:./readme.txt
2021-12-28 21:15:23,417: DEBUG: this file/folder has "."
2021-12-28 21:15:23,417: DEBUG: found:./requirements.txt
2021-12-28 21:15:23,417: DEBUG: this file/folder has "."
2021-12-28 21:15:23,417: DEBUG: found:./runtime.txt
2021-12-28 21:15:23,417: DEBUG: this file/folder has "."
2021-12-28 21:15:23,418: DEBUG: found:./test.py
2021-12-28 21:15:23,418: DEBUG: this file/folder has "."
2021-12-28 21:15:23,418: DEBUG: found:./testapp
2021-12-28 21:15:23,418: DEBUG:     this is APP
2021-12-28 21:15:23,422: DEBUG: found:./__init__.py
2021-12-28 21:15:23,422: DEBUG: this file/folder has "."
2021-12-28 21:15:23,422: DEBUG: found:./__pycache__
2021-12-28 21:15:23,422: DEBUG: this folder has NOT app.py or settings.py
2021-12-28 21:15:23,422: INFO: ---------- 関数.get_autorun_app_list 実行 ----------
2021-12-28 21:15:23,423: INFO: [実行元]C:\Users\kizuk\Desktop\git\python-garage\autorun_manager\app.py 223行目 <module>
2021-12-28 21:15:23,423: INFO: [実行元]C:\Users\kizuk\Desktop\git\python-garage\autorun_manager\..\modules\easylogger.py 76行目 _decoration_func
2021-12-28 21:15:23,423: INFO: ---------- start get_autorun_app_list() ----------
2021-12-28 21:15:23,424: DEBUG: in [AUTORUN APP LIST]
2021-12-28 21:15:23,424: DEBUG: found:auto_bt_check = True,1
2021-12-28 21:15:23,424: DEBUG: found:auto_mail_check = True,3
2021-12-28 21:15:23,424: DEBUG: found:auto_manga_check = True,3
2021-12-28 21:15:23,425: INFO: ---------- end get_autorun_app_list() ----------
2021-12-28 21:15:23,425: INFO: delete:auto_manga_check
2021-12-28 21:15:23,425: INFO: ---------- end add_newapps() ----------
2021-12-28 21:15:23,426: INFO: ---------- 関数.run_all_apps 実行 ----------
2021-12-28 21:15:23,426: INFO: [実行元]C:\Users\kizuk\Desktop\git\python-garage\autorun_manager\app.py 224行目 <module>
2021-12-28 21:15:23,426: INFO: [実行元]C:\Users\kizuk\Desktop\git\python-garage\autorun_manager\..\modules\easylogger.py 72行目 _decoration_func
2021-12-28 21:15:23,439: INFO: ---------- 関数.run_app 実行 ----------
2021-12-28 21:15:23,441: INFO: [実行元]C:\Users\kizuk\Desktop\git\python-garage\autorun_manager\app.py 224行目 <module>
2021-12-28 21:15:23,441: INFO: [実行元]C:\Users\kizuk\Desktop\git\python-garage\autorun_manager\..\modules\easylogger.py 76行目 _decoration_func
2021-12-28 21:15:23,442: DEBUG: {'auto_bt_check': [['2021/12/04 12:13', '\n既に入力済み：「堀見」「井谷」「石塚」「椋下」\n入力完了：なし\nエラー：なし'], ['2021/12/04 11:41', 'NameError: name \'es\' is not defined [auto_bt_check/app.py][line:101]\n\nTraceback (most recent call last):\n  File "C:\\Users\\kizuk\\Desktop\\git\\python-garage\\autorun_manager\\..\\auto_bt_check\\app.py", line 101, in run\n    status = health_check(name,list)\n  File "C:\\Users\\kizuk\\Desktop\\git\\python-garage\\autorun_manager\\..\\auto_bt_check\\app.py", line 50, in health_check\n    es.write_all([[\'input#username\',true_list[0]],[\'input#password\',true_list[1]]])\nNameError: name \'es\' is not defined\n'], ['2021/12/04 11:35', '\n既に入力済み：「堀見」「井谷」「石塚」「椋下」\n入力完了：なし\nエラー：なし'], ['2021/12/04 11:30', '\n既に入力済み：「堀見」「井谷」「石塚」「椋下」\n入力完了：なし\nエラー：なし'], ['2021/12/04 11:24', '\n既に入力済み：「堀見」「井谷」「石塚」「椋下」\n入力完了：なし\nエラー：なし']], 'auto_mail_check': [['2021/12/04 12:14', None], ['2021/12/04 11:42', None], ['2021/12/04 11:36', None], ['2021/12/04 11:31', None], ['2021/12/04 11:25', None]], 'auto_manga_check': [['2021/12/04 12:14', '']]}
2021-12-28 21:15:24,730: INFO: 実行：auto_bt_check.py
2021-12-28 21:16:32,722: DEBUG: [['2021/12/28 21:16', None]]
2021-12-28 21:16:32,722: DEBUG: [['2021/12/28 21:16', None], ['2021/12/04 12:13', '\n既に入力済み：「堀見」「井谷」「石塚」「椋下」\n入力完了：なし\nエラー：なし'], ['2021/12/04 11:41', 'NameError: name \'es\' is not defined [auto_bt_check/app.py][line:101]\n\nTraceback (most recent call last):\n  File "C:\\Users\\kizuk\\Desktop\\git\\python-garage\\autorun_manager\\..\\auto_bt_check\\app.py", line 101, in run\n    status = health_check(name,list)\n  File "C:\\Users\\kizuk\\Desktop\\git\\python-garage\\autorun_manager\\..\\auto_bt_check\\app.py", line 50, in health_check\n    es.write_all([[\'input#username\',true_list[0]],[\'input#password\',true_list[1]]])\nNameError: name \'es\' is not defined\n'], ['2021/12/04 11:35', '\n既に入力済み：「堀見」「井谷」「石塚」「椋下」\n入力完了：なし\nエラー：なし'], ['2021/12/04 11:30', '\n既に入力済み：「堀見」「井谷」「石塚」「椋下」\n入力完了：なし\nエラー：なし'], ['2021/12/04 11:24', '\n既に入力済み：「堀見」「井谷」「石塚」「椋下」\n入力完了：なし\nエラー：なし']]
2021-12-28 21:16:32,722: DEBUG: {'auto_bt_check': [['2021/12/28 21:16', None], ['2021/12/04 12:13', '\n既に入力済み：「堀見」「井谷」「石塚」「椋下」\n入力完了：なし\nエラー：なし'], ['2021/12/04 11:41', 'NameError: name \'es\' is not defined [auto_bt_check/app.py][line:101]\n\nTraceback (most recent call last):\n  File "C:\\Users\\kizuk\\Desktop\\git\\python-garage\\autorun_manager\\..\\auto_bt_check\\app.py", line 101, in run\n    status = health_check(name,list)\n  File "C:\\Users\\kizuk\\Desktop\\git\\python-garage\\autorun_manager\\..\\auto_bt_check\\app.py", line 50, in health_check\n    es.write_all([[\'input#username\',true_list[0]],[\'input#password\',true_list[1]]])\nNameError: name \'es\' is not defined\n'], ['2021/12/04 11:35', '\n既に入力済み：「堀見」「井谷」「石塚」「椋下」\n入力完了：なし\nエラー：なし'], ['2021/12/04 11:30', '\n既に入力済み：「堀見」「井谷」「石塚」「椋下」\n入力完了：なし\nエラー：なし']], 'auto_mail_check': [['2021/12/04 12:14', None], ['2021/12/04 11:42', None], ['2021/12/04 11:36', None], ['2021/12/04 11:31', None], ['2021/12/04 11:25', None]], 'auto_manga_check': [['2021/12/04 12:14', '']]}
2021-12-28 21:16:32,722: INFO: ---------- 関数.run_app 実行 ----------
2021-12-28 21:16:32,722: INFO: [実行元]C:\Users\kizuk\Desktop\git\python-garage\autorun_manager\app.py 224行目 <module>
2021-12-28 21:16:32,722: INFO: [実行元]C:\Users\kizuk\Desktop\git\python-garage\autorun_manager\..\modules\easylogger.py 76行目 _decoration_func
2021-12-28 21:16:32,735: DEBUG: {'auto_bt_check': [['2021/12/28 21:16', None], ['2021/12/04 12:13', '\n既に入力済み：「堀見」「井谷」「石塚」「椋下」\n入力完了：なし\nエラー：なし'], ['2021/12/04 11:41', 'NameError: name \'es\' is not defined [auto_bt_check/app.py][line:101]\n\nTraceback (most recent call last):\n  File "C:\\Users\\kizuk\\Desktop\\git\\python-garage\\autorun_manager\\..\\auto_bt_check\\app.py", line 101, in run\n    status = health_check(name,list)\n  File "C:\\Users\\kizuk\\Desktop\\git\\python-garage\\autorun_manager\\..\\auto_bt_check\\app.py", line 50, in health_check\n    es.write_all([[\'input#username\',true_list[0]],[\'input#password\',true_list[1]]])\nNameError: name \'es\' is not defined\n'], ['2021/12/04 11:35', '\n既に入力済み：「堀見」「井谷」「石塚」「椋下」\n入力完了：なし\nエラー：なし'], ['2021/12/04 11:30', '\n既に入力済み：「堀見」「井谷」「石塚」「椋下」\n入力完了：なし\nエラー：なし']], 'auto_mail_check': [['2021/12/04 12:14', None], ['2021/12/04 11:42', None], ['2021/12/04 11:36', None], ['2021/12/04 11:31', None], ['2021/12/04 11:25', None]], 'auto_manga_check': [['2021/12/04 12:14', '']]}
2021-12-28 21:16:32,735: INFO: 実行：auto_bt_check.py
2021-12-28 21:16:53,354: INFO: ---------- 関数.check_all_apps_status 実行 ----------
2021-12-28 21:16:53,424: INFO: [実行元]C:\Users\kizuk\Desktop\git\python-garage\autorun_manager\app.py 223行目 <module>
2021-12-28 21:16:53,424: INFO: [実行元]C:\Users\kizuk\Desktop\git\python-garage\autorun_manager\..\modules\easylogger.py 72行目 _decoration_func
2021-12-28 21:16:53,424: INFO: ---------- start add_newapps() ----------
2021-12-28 21:16:53,424: DEBUG: found:./.env
2021-12-28 21:16:53,424: DEBUG: this file/folder has "."
2021-12-28 21:16:53,424: DEBUG: found:./.git
2021-12-28 21:16:53,425: DEBUG: this file/folder has "."
2021-12-28 21:16:53,425: DEBUG: found:./.gitignore
2021-12-28 21:16:53,425: DEBUG: this file/folder has "."
2021-12-28 21:16:53,425: DEBUG: found:./.venv
2021-12-28 21:16:53,425: DEBUG: this file/folder has "."
2021-12-28 21:16:53,425: DEBUG: found:./app_template
2021-12-28 21:16:53,425: DEBUG: this file/folder is app_template
2021-12-28 21:16:53,425: DEBUG: found:./autorun_manager
2021-12-28 21:16:53,425: DEBUG: this file/folder is autorun_manager
2021-12-28 21:16:53,425: DEBUG: found:./auto_bt_check
2021-12-28 21:16:53,426: DEBUG:     this is APP
2021-12-28 21:16:53,428: INFO:     [auto_bt_check/settings.py]APP_FOR_AUTO_RUN = True, RUN_FREQUENCY = 1
2021-12-28 21:16:53,428: DEBUG: found:./auto_mail_check
2021-12-28 21:16:53,428: DEBUG:     this is APP
2021-12-28 21:16:53,430: INFO:     [auto_mail_check/settings.py]APP_FOR_AUTO_RUN = True, RUN_FREQUENCY = 10
2021-12-28 21:16:53,430: DEBUG: found:./auto_manga_check
2021-12-28 21:16:53,430: DEBUG: this folder has NOT app.py or settings.py
2021-12-28 21:16:53,430: DEBUG: found:./check.html
2021-12-28 21:16:53,430: DEBUG: this file/folder has "."
2021-12-28 21:16:53,430: DEBUG: found:./config.py
2021-12-28 21:16:53,431: DEBUG: this file/folder has "."
2021-12-28 21:16:53,431: DEBUG: found:./data
2021-12-28 21:16:53,431: DEBUG: this folder has NOT app.py or settings.py
2021-12-28 21:16:53,431: DEBUG: found:./flask_platform
2021-12-28 21:16:53,431: DEBUG:     this is APP
2021-12-28 21:16:53,433: DEBUG: found:./for_offline
2021-12-28 21:16:53,434: DEBUG: this folder has NOT app.py or settings.py
2021-12-28 21:16:53,434: DEBUG: found:./manage.py
2021-12-28 21:16:53,434: DEBUG: this file/folder has "."
2021-12-28 21:16:53,434: DEBUG: found:./modules
2021-12-28 21:16:53,434: DEBUG: this folder has NOT app.py or settings.py
2021-12-28 21:16:53,434: DEBUG: found:./Procfile
2021-12-28 21:16:53,434: DEBUG: this is NOT folder
2021-12-28 21:16:53,435: DEBUG: found:./readme.txt
2021-12-28 21:16:53,435: DEBUG: this file/folder has "."
2021-12-28 21:16:53,435: DEBUG: found:./requirements.txt
2021-12-28 21:16:53,435: DEBUG: this file/folder has "."
2021-12-28 21:16:53,435: DEBUG: found:./runtime.txt
2021-12-28 21:16:53,435: DEBUG: this file/folder has "."
2021-12-28 21:16:53,435: DEBUG: found:./test.py
2021-12-28 21:16:53,435: DEBUG: this file/folder has "."
2021-12-28 21:16:53,435: DEBUG: found:./testapp
2021-12-28 21:16:53,436: DEBUG:     this is APP
2021-12-28 21:16:53,438: DEBUG: found:./__init__.py
2021-12-28 21:16:53,438: DEBUG: this file/folder has "."
2021-12-28 21:16:53,438: DEBUG: found:./__pycache__
2021-12-28 21:16:53,438: DEBUG: this folder has NOT app.py or settings.py
2021-12-28 21:16:53,439: INFO: ---------- 関数.get_autorun_app_list 実行 ----------
2021-12-28 21:16:53,439: INFO: [実行元]C:\Users\kizuk\Desktop\git\python-garage\autorun_manager\app.py 223行目 <module>
2021-12-28 21:16:53,439: INFO: [実行元]C:\Users\kizuk\Desktop\git\python-garage\autorun_manager\..\modules\easylogger.py 76行目 _decoration_func
2021-12-28 21:16:53,440: INFO: ---------- start get_autorun_app_list() ----------
2021-12-28 21:16:53,440: DEBUG: in [AUTORUN APP LIST]
2021-12-28 21:16:53,440: DEBUG: found:auto_bt_check = True,1
2021-12-28 21:16:53,440: DEBUG: found:auto_mail_check = True,3
2021-12-28 21:16:53,441: INFO: ---------- end get_autorun_app_list() ----------
2021-12-28 21:16:53,442: INFO: ---------- end add_newapps() ----------
2021-12-28 21:16:53,442: INFO: ---------- 関数.run_all_apps 実行 ----------
2021-12-28 21:16:53,443: INFO: [実行元]C:\Users\kizuk\Desktop\git\python-garage\autorun_manager\app.py 224行目 <module>
2021-12-28 21:16:53,443: INFO: [実行元]C:\Users\kizuk\Desktop\git\python-garage\autorun_manager\..\modules\easylogger.py 72行目 _decoration_func
2021-12-28 21:16:53,443: INFO: ---------- 関数.run_app 実行 ----------
2021-12-28 21:16:53,444: INFO: [実行元]C:\Users\kizuk\Desktop\git\python-garage\autorun_manager\app.py 224行目 <module>
2021-12-28 21:16:53,445: INFO: [実行元]C:\Users\kizuk\Desktop\git\python-garage\autorun_manager\..\modules\easylogger.py 76行目 _decoration_func
2021-12-28 21:16:53,445: DEBUG: {'auto_bt_check': [['2021/12/28 21:16', None], ['2021/12/04 12:13', '\n既に入力済み：「堀見」「井谷」「石塚」「椋下」\n入力完了：なし\nエラー：なし'], ['2021/12/04 11:41', 'NameError: name \'es\' is not defined [auto_bt_check/app.py][line:101]\n\nTraceback (most recent call last):\n  File "C:\\Users\\kizuk\\Desktop\\git\\python-garage\\autorun_manager\\..\\auto_bt_check\\app.py", line 101, in run\n    status = health_check(name,list)\n  File "C:\\Users\\kizuk\\Desktop\\git\\python-garage\\autorun_manager\\..\\auto_bt_check\\app.py", line 50, in health_check\n    es.write_all([[\'input#username\',true_list[0]],[\'input#password\',true_list[1]]])\nNameError: name \'es\' is not defined\n'], ['2021/12/04 11:35', '\n既に入力済み：「堀見」「井谷」「石塚」「椋下」\n入力完了：なし\nエラー：なし'], ['2021/12/04 11:30', '\n既に入力済み：「堀見」「井谷」「石塚」「椋下」\n入力完了：なし\nエラー：なし']], 'auto_mail_check': [['2021/12/04 12:14', None], ['2021/12/04 11:42', None], ['2021/12/04 11:36', None], ['2021/12/04 11:31', None], ['2021/12/04 11:25', None]], 'auto_manga_check': [['2021/12/04 12:14', '']]}
2021-12-28 21:16:54,682: INFO: 実行：auto_bt_check.py
2021-12-28 21:17:57,935: DEBUG: [['2021/12/28 21:17', None]]
2021-12-28 21:17:57,935: DEBUG: [['2021/12/28 21:17', None], ['2021/12/28 21:16', None], ['2021/12/04 12:13', '\n既に入力済み：「堀見」「井谷」「石塚」「椋下」\n入力完了：なし\nエラー：なし'], ['2021/12/04 11:41', 'NameError: name \'es\' is not defined [auto_bt_check/app.py][line:101]\n\nTraceback (most recent call last):\n  File "C:\\Users\\kizuk\\Desktop\\git\\python-garage\\autorun_manager\\..\\auto_bt_check\\app.py", line 101, in run\n    status = health_check(name,list)\n  File "C:\\Users\\kizuk\\Desktop\\git\\python-garage\\autorun_manager\\..\\auto_bt_check\\app.py", line 50, in health_check\n    es.write_all([[\'input#username\',true_list[0]],[\'input#password\',true_list[1]]])\nNameError: name \'es\' is not defined\n'], ['2021/12/04 11:35', '\n既に入力済み：「堀見」「井谷」「石塚」「椋下」\n入力完了：なし\nエラー：なし'], ['2021/12/04 11:30', '\n既に入力済み：「堀見」「井谷」「石塚」「椋下」\n入力完了：なし\nエラー：なし']]
2021-12-28 21:17:57,935: DEBUG: {'auto_bt_check': [['2021/12/28 21:17', None], ['2021/12/28 21:16', None], ['2021/12/04 12:13', '\n既に入力済み：「堀見」「井谷」「石塚」「椋下」\n入力完了：なし\nエラー：なし'], ['2021/12/04 11:41', 'NameError: name \'es\' is not defined [auto_bt_check/app.py][line:101]\n\nTraceback (most recent call last):\n  File "C:\\Users\\kizuk\\Desktop\\git\\python-garage\\autorun_manager\\..\\auto_bt_check\\app.py", line 101, in run\n    status = health_check(name,list)\n  File "C:\\Users\\kizuk\\Desktop\\git\\python-garage\\autorun_manager\\..\\auto_bt_check\\app.py", line 50, in health_check\n    es.write_all([[\'input#username\',true_list[0]],[\'input#password\',true_list[1]]])\nNameError: name \'es\' is not defined\n'], ['2021/12/04 11:35', '\n既に入力済み：「堀見」「井谷」「石塚」「椋下」\n入力完了：なし\nエラー：なし']], 'auto_mail_check': [['2021/12/04 12:14', None], ['2021/12/04 11:42', None], ['2021/12/04 11:36', None], ['2021/12/04 11:31', None], ['2021/12/04 11:25', None]], 'auto_manga_check': [['2021/12/04 12:14', '']]}
2021-12-28 21:17:57,943: INFO: ---------- 関数.run_app 実行 ----------
2021-12-28 21:17:57,944: INFO: [実行元]C:\Users\kizuk\Desktop\git\python-garage\autorun_manager\app.py 224行目 <module>
2021-12-28 21:17:57,944: INFO: [実行元]C:\Users\kizuk\Desktop\git\python-garage\autorun_manager\..\modules\easylogger.py 76行目 _decoration_func
2021-12-28 21:17:57,954: DEBUG: {'auto_bt_check': [['2021/12/28 21:17', None], ['2021/12/28 21:16', None], ['2021/12/04 12:13', '\n既に入力済み：「堀見」「井谷」「石塚」「椋下」\n入力完了：なし\nエラー：なし'], ['2021/12/04 11:41', 'NameError: name \'es\' is not defined [auto_bt_check/app.py][line:101]\n\nTraceback (most recent call last):\n  File "C:\\Users\\kizuk\\Desktop\\git\\python-garage\\autorun_manager\\..\\auto_bt_check\\app.py", line 101, in run\n    status = health_check(name,list)\n  File "C:\\Users\\kizuk\\Desktop\\git\\python-garage\\autorun_manager\\..\\auto_bt_check\\app.py", line 50, in health_check\n    es.write_all([[\'input#username\',true_list[0]],[\'input#password\',true_list[1]]])\nNameError: name \'es\' is not defined\n'], ['2021/12/04 11:35', '\n既に入力済み：「堀見」「井谷」「石塚」「椋下」\n入力完了：なし\nエラー：なし']], 'auto_mail_check': [['2021/12/04 12:14', None], ['2021/12/04 11:42', None], ['2021/12/04 11:36', None], ['2021/12/04 11:31', None], ['2021/12/04 11:25', None]], 'auto_manga_check': [['2021/12/04 12:14', '']]}
2021-12-28 21:17:59,233: INFO: 実行：auto_mail_check.py
2021-12-28 21:18:51,449: DEBUG: [['2021/12/28 21:18', None]]
2021-12-28 21:18:51,449: DEBUG: [['2021/12/28 21:18', None], ['2021/12/04 12:14', None], ['2021/12/04 11:42', None], ['2021/12/04 11:36', None], ['2021/12/04 11:31', None], ['2021/12/04 11:25', None]]
2021-12-28 21:18:51,449: DEBUG: {'auto_bt_check': [['2021/12/28 21:17', None], ['2021/12/28 21:16', None], ['2021/12/04 12:13', '\n既に入力済み：「堀見」「井谷」「石塚」「椋下」\n入力完了：なし\nエラー：なし'], ['2021/12/04 11:41', 'NameError: name \'es\' is not defined [auto_bt_check/app.py][line:101]\n\nTraceback (most recent call last):\n  File "C:\\Users\\kizuk\\Desktop\\git\\python-garage\\autorun_manager\\..\\auto_bt_check\\app.py", line 101, in run\n    status = health_check(name,list)\n  File "C:\\Users\\kizuk\\Desktop\\git\\python-garage\\autorun_manager\\..\\auto_bt_check\\app.py", line 50, in health_check\n    es.write_all([[\'input#username\',true_list[0]],[\'input#password\',true_list[1]]])\nNameError: name \'es\' is not defined\n'], ['2021/12/04 11:35', '\n既に入力済み：「堀見」「井谷」「石塚」「椋下」\n入力完了：なし\nエラー：なし']], 'auto_mail_check': [['2021/12/28 21:18', None], ['2021/12/04 12:14', None], ['2021/12/04 11:42', None], ['2021/12/04 11:36', None], ['2021/12/04 11:31', None]], 'auto_manga_check': [['2021/12/04 12:14', '']]}
2021-12-28 21:18:51,450: INFO: ---------- 関数.run_app 実行 ----------
2021-12-28 21:18:51,451: INFO: [実行元]C:\Users\kizuk\Desktop\git\python-garage\autorun_manager\app.py 224行目 <module>
2021-12-28 21:18:51,451: INFO: [実行元]C:\Users\kizuk\Desktop\git\python-garage\autorun_manager\..\modules\easylogger.py 76行目 _decoration_func
2021-12-28 21:18:51,460: DEBUG: {'auto_bt_check': [['2021/12/28 21:17', None], ['2021/12/28 21:16', None], ['2021/12/04 12:13', '\n既に入力済み：「堀見」「井谷」「石塚」「椋下」\n入力完了：なし\nエラー：なし'], ['2021/12/04 11:41', 'NameError: name \'es\' is not defined [auto_bt_check/app.py][line:101]\n\nTraceback (most recent call last):\n  File "C:\\Users\\kizuk\\Desktop\\git\\python-garage\\autorun_manager\\..\\auto_bt_check\\app.py", line 101, in run\n    status = health_check(name,list)\n  File "C:\\Users\\kizuk\\Desktop\\git\\python-garage\\autorun_manager\\..\\auto_bt_check\\app.py", line 50, in health_check\n    es.write_all([[\'input#username\',true_list[0]],[\'input#password\',true_list[1]]])\nNameError: name \'es\' is not defined\n'], ['2021/12/04 11:35', '\n既に入力済み：「堀見」「井谷」「石塚」「椋下」\n入力完了：なし\nエラー：なし']], 'auto_mail_check': [['2021/12/28 21:18', None], ['2021/12/04 12:14', None], ['2021/12/04 11:42', None], ['2021/12/04 11:36', None], ['2021/12/04 11:31', None]], 'auto_manga_check': [['2021/12/04 12:14', '']]}
2021-12-28 21:18:51,461: INFO: 実行：auto_mail_check.py
2021-12-28 21:18:59,603: ERROR: urllib3.exceptions.MaxRetryError: HTTPConnectionPool(host='127.0.0.1', port=62734): Max retries exceeded with url: /session/6c4209fa23b4d684df15f5a5ed3a5523/url (Caused by NewConnectionError('<urllib3.connection.HTTPConnection object at 0x009FD298>: Failed to establish a new connection: [WinError 10061] 対象のコンピューターによって拒否されたため、接続できませんでした。')) [autorun_manager/app.py][line:158]

Traceback (most recent call last):
  File "C:\Users\kizuk\AppData\Local\Programs\Python\Python38-32\lib\site-packages\urllib3\connection.py", line 159, in _new_conn
    conn = connection.create_connection(
  File "C:\Users\kizuk\AppData\Local\Programs\Python\Python38-32\lib\site-packages\urllib3\util\connection.py", line 84, in create_connection
    raise err
  File "C:\Users\kizuk\AppData\Local\Programs\Python\Python38-32\lib\site-packages\urllib3\util\connection.py", line 74, in create_connection
    sock.connect(sa)
ConnectionRefusedError: [WinError 10061] 対象のコンピューターによって拒否されたため、接続できませんでした。

During handling of the above exception, another exception occurred:

Traceback (most recent call last):
  File "C:\Users\kizuk\AppData\Local\Programs\Python\Python38-32\lib\site-packages\urllib3\connectionpool.py", line 670, in urlopen
    httplib_response = self._make_request(
  File "C:\Users\kizuk\AppData\Local\Programs\Python\Python38-32\lib\site-packages\urllib3\connectionpool.py", line 392, in _make_request
    conn.request(method, url, **httplib_request_kw)
  File "C:\Users\kizuk\AppData\Local\Programs\Python\Python38-32\lib\http\client.py", line 1240, in request
    self._send_request(method, url, body, headers, encode_chunked)
  File "C:\Users\kizuk\AppData\Local\Programs\Python\Python38-32\lib\http\client.py", line 1286, in _send_request
    self.endheaders(body, encode_chunked=encode_chunked)
  File "C:\Users\kizuk\AppData\Local\Programs\Python\Python38-32\lib\http\client.py", line 1235, in endheaders
    self._send_output(message_body, encode_chunked=encode_chunked)
  File "C:\Users\kizuk\AppData\Local\Programs\Python\Python38-32\lib\http\client.py", line 1006, in _send_output
    self.send(msg)
  File "C:\Users\kizuk\AppData\Local\Programs\Python\Python38-32\lib\http\client.py", line 946, in send
    self.connect()
  File "C:\Users\kizuk\AppData\Local\Programs\Python\Python38-32\lib\site-packages\urllib3\connection.py", line 187, in connect
    conn = self._new_conn()
  File "C:\Users\kizuk\AppData\Local\Programs\Python\Python38-32\lib\site-packages\urllib3\connection.py", line 171, in _new_conn
    raise NewConnectionError(
urllib3.exceptions.NewConnectionError: <urllib3.connection.HTTPConnection object at 0x009FD298>: Failed to establish a new connection: [WinError 10061] 対象のコンピューターによって拒否されたため、接続できませんでした。

During handling of the above exception, another exception occurred:

Traceback (most recent call last):
  File "C:\Users\kizuk\Desktop\git\python-garage\autorun_manager\app.py", line 158, in run_all_apps
    run_app(key)
  File "C:\Users\kizuk\Desktop\git\python-garage\autorun_manager\..\modules\easylogger.py", line 76, in _decoration_func
    return func(*args, **kwargs)
  File "C:\Users\kizuk\Desktop\git\python-garage\autorun_manager\app.py", line 171, in run_app
    result_text = app.run()
  File "C:\Users\kizuk\Desktop\git\python-garage\autorun_manager\..\auto_mail_check\app.py", line 113, in run
    es.get('https://webmail.jikei.ac.jp/',sleeptime=5)
  File "C:\Users\kizuk\Desktop\git\python-garage\autorun_manager\..\modules\easyselenium.py", line 56, in get
    self.driver.get(url)
  File "C:\Users\kizuk\AppData\Local\Programs\Python\Python38-32\lib\site-packages\selenium\webdriver\remote\webdriver.py", line 333, in get
    self.execute(Command.GET, {'url': url})
  File "C:\Users\kizuk\AppData\Local\Programs\Python\Python38-32\lib\site-packages\selenium\webdriver\remote\webdriver.py", line 319, in execute
    response = self.command_executor.execute(driver_command, params)
  File "C:\Users\kizuk\AppData\Local\Programs\Python\Python38-32\lib\site-packages\selenium\webdriver\remote\remote_connection.py", line 374, in execute
    return self._request(command_info[0], url, body=data)
  File "C:\Users\kizuk\AppData\Local\Programs\Python\Python38-32\lib\site-packages\selenium\webdriver\remote\remote_connection.py", line 397, in _request
    resp = self._conn.request(method, url, body=body, headers=headers)
  File "C:\Users\kizuk\AppData\Local\Programs\Python\Python38-32\lib\site-packages\urllib3\request.py", line 79, in request
    return self.request_encode_body(
  File "C:\Users\kizuk\AppData\Local\Programs\Python\Python38-32\lib\site-packages\urllib3\request.py", line 171, in request_encode_body
    return self.urlopen(method, url, **extra_kw)
  File "C:\Users\kizuk\AppData\Local\Programs\Python\Python38-32\lib\site-packages\urllib3\poolmanager.py", line 336, in urlopen
    response = conn.urlopen(method, u.request_uri, **kw)
  File "C:\Users\kizuk\AppData\Local\Programs\Python\Python38-32\lib\site-packages\urllib3\connectionpool.py", line 752, in urlopen
    return self.urlopen(
  File "C:\Users\kizuk\AppData\Local\Programs\Python\Python38-32\lib\site-packages\urllib3\connectionpool.py", line 752, in urlopen
    return self.urlopen(
  File "C:\Users\kizuk\AppData\Local\Programs\Python\Python38-32\lib\site-packages\urllib3\connectionpool.py", line 752, in urlopen
    return self.urlopen(
  File "C:\Users\kizuk\AppData\Local\Programs\Python\Python38-32\lib\site-packages\urllib3\connectionpool.py", line 724, in urlopen
    retries = retries.increment(
  File "C:\Users\kizuk\AppData\Local\Programs\Python\Python38-32\lib\site-packages\urllib3\util\retry.py", line 439, in increment
    raise MaxRetryError(_pool, url, error or ResponseError(cause))
urllib3.exceptions.MaxRetryError: HTTPConnectionPool(host='127.0.0.1', port=62734): Max retries exceeded with url: /session/6c4209fa23b4d684df15f5a5ed3a5523/url (Caused by NewConnectionError('<urllib3.connection.HTTPConnection object at 0x009FD298>: Failed to establish a new connection: [WinError 10061] 対象のコンピューターによって拒否されたため、接続できませんでした。'))

2021-12-29 11:41:38,408: INFO: ---------- 関数.check_all_apps_status 実行 ----------
2021-12-29 11:41:38,478: INFO: [実行元]C:\Users\kizuk\Desktop\git\python-garage\autorun_manager\app.py 223行目 <module>
2021-12-29 11:41:38,478: INFO: [実行元]C:\Users\kizuk\Desktop\git\python-garage\autorun_manager\..\modules\easylogger.py 72行目 _decoration_func
2021-12-29 11:41:38,478: INFO: ---------- start add_newapps() ----------
2021-12-29 11:41:38,478: DEBUG: found:./.env
2021-12-29 11:41:38,478: DEBUG: this file/folder has "."
2021-12-29 11:41:38,478: DEBUG: found:./.git
2021-12-29 11:41:38,478: DEBUG: this file/folder has "."
2021-12-29 11:41:38,483: DEBUG: found:./.gitignore
2021-12-29 11:41:38,483: DEBUG: this file/folder has "."
2021-12-29 11:41:38,483: DEBUG: found:./.venv
2021-12-29 11:41:38,483: DEBUG: this file/folder has "."
2021-12-29 11:41:38,483: DEBUG: found:./app_template
2021-12-29 11:41:38,483: DEBUG: this file/folder is app_template
2021-12-29 11:41:38,483: DEBUG: found:./autorun_manager
2021-12-29 11:41:38,483: DEBUG: this file/folder is autorun_manager
2021-12-29 11:41:38,483: DEBUG: found:./auto_bt_check
2021-12-29 11:41:38,484: DEBUG:     this is APP
2021-12-29 11:41:38,486: INFO:     [auto_bt_check/settings.py]APP_FOR_AUTO_RUN = True, RUN_FREQUENCY = 1
2021-12-29 11:41:38,486: DEBUG: found:./auto_mail_check
2021-12-29 11:41:38,486: DEBUG:     this is APP
2021-12-29 11:41:38,488: INFO:     [auto_mail_check/settings.py]APP_FOR_AUTO_RUN = True, RUN_FREQUENCY = 10
2021-12-29 11:41:38,489: DEBUG: found:./auto_manga_check
2021-12-29 11:41:38,489: DEBUG:     this is APP
2021-12-29 11:41:38,501: INFO:     [auto_manga_check/settings.py]APP_FOR_AUTO_RUN = True, RUN_FREQUENCY = 10
2021-12-29 11:41:38,501: DEBUG: found:./check.html
2021-12-29 11:41:38,502: DEBUG: this file/folder has "."
2021-12-29 11:41:38,502: DEBUG: found:./config.py
2021-12-29 11:41:38,502: DEBUG: this file/folder has "."
2021-12-29 11:41:38,502: DEBUG: found:./data
2021-12-29 11:41:38,502: DEBUG: this folder has NOT app.py or settings.py
2021-12-29 11:41:38,502: DEBUG: found:./flask_platform
2021-12-29 11:41:38,503: DEBUG:     this is APP
2021-12-29 11:41:38,508: DEBUG: found:./for_offline
2021-12-29 11:41:38,508: DEBUG: this folder has NOT app.py or settings.py
2021-12-29 11:41:38,508: DEBUG: found:./manage.py
2021-12-29 11:41:38,509: DEBUG: this file/folder has "."
2021-12-29 11:41:38,509: DEBUG: found:./modules
2021-12-29 11:41:38,509: DEBUG: this folder has NOT app.py or settings.py
2021-12-29 11:41:38,509: DEBUG: found:./Procfile
2021-12-29 11:41:38,509: DEBUG: this is NOT folder
2021-12-29 11:41:38,509: DEBUG: found:./readme.txt
2021-12-29 11:41:38,509: DEBUG: this file/folder has "."
2021-12-29 11:41:38,509: DEBUG: found:./requirements.txt
2021-12-29 11:41:38,510: DEBUG: this file/folder has "."
2021-12-29 11:41:38,510: DEBUG: found:./runtime.txt
2021-12-29 11:41:38,510: DEBUG: this file/folder has "."
2021-12-29 11:41:38,510: DEBUG: found:./test.py
2021-12-29 11:41:38,510: DEBUG: this file/folder has "."
2021-12-29 11:41:38,510: DEBUG: found:./testapp
2021-12-29 11:41:38,510: DEBUG:     this is APP
2021-12-29 11:41:38,513: DEBUG: found:./__init__.py
2021-12-29 11:41:38,513: DEBUG: this file/folder has "."
2021-12-29 11:41:38,513: DEBUG: found:./__pycache__
2021-12-29 11:41:38,514: DEBUG: this folder has NOT app.py or settings.py
2021-12-29 11:41:38,514: INFO: ---------- 関数.get_autorun_app_list 実行 ----------
2021-12-29 11:41:38,515: INFO: [実行元]C:\Users\kizuk\Desktop\git\python-garage\autorun_manager\app.py 223行目 <module>
2021-12-29 11:41:38,515: INFO: [実行元]C:\Users\kizuk\Desktop\git\python-garage\autorun_manager\..\modules\easylogger.py 76行目 _decoration_func
2021-12-29 11:41:38,515: INFO: ---------- start get_autorun_app_list() ----------
2021-12-29 11:41:38,515: DEBUG: in [AUTORUN APP LIST]
2021-12-29 11:41:38,516: DEBUG: found:auto_bt_check = True,1
2021-12-29 11:41:38,516: DEBUG: found:auto_mail_check = True,3
2021-12-29 11:41:38,516: INFO: ---------- end get_autorun_app_list() ----------
2021-12-29 11:41:38,516: INFO: add:['auto_manga_check', '10'] = True,0
2021-12-29 11:41:38,517: INFO: ---------- end add_newapps() ----------
2021-12-29 11:41:38,517: INFO: ---------- 関数.run_all_apps 実行 ----------
2021-12-29 11:41:38,518: INFO: [実行元]C:\Users\kizuk\Desktop\git\python-garage\autorun_manager\app.py 224行目 <module>
2021-12-29 11:41:38,518: INFO: [実行元]C:\Users\kizuk\Desktop\git\python-garage\autorun_manager\..\modules\easylogger.py 72行目 _decoration_func
2021-12-29 11:41:38,529: INFO: ---------- 関数.run_app 実行 ----------
2021-12-29 11:41:38,530: INFO: [実行元]C:\Users\kizuk\Desktop\git\python-garage\autorun_manager\app.py 224行目 <module>
2021-12-29 11:41:38,530: INFO: [実行元]C:\Users\kizuk\Desktop\git\python-garage\autorun_manager\..\modules\easylogger.py 76行目 _decoration_func
2021-12-29 11:41:38,531: DEBUG: {'auto_bt_check': [['2021/12/28 21:17', None], ['2021/12/28 21:16', None], ['2021/12/04 12:13', '\n既に入力済み：「堀見」「井谷」「石塚」「椋下」\n入力完了：なし\nエラー：なし'], ['2021/12/04 11:41', 'NameError: name \'es\' is not defined [auto_bt_check/app.py][line:101]\n\nTraceback (most recent call last):\n  File "C:\\Users\\kizuk\\Desktop\\git\\python-garage\\autorun_manager\\..\\auto_bt_check\\app.py", line 101, in run\n    status = health_check(name,list)\n  File "C:\\Users\\kizuk\\Desktop\\git\\python-garage\\autorun_manager\\..\\auto_bt_check\\app.py", line 50, in health_check\n    es.write_all([[\'input#username\',true_list[0]],[\'input#password\',true_list[1]]])\nNameError: name \'es\' is not defined\n'], ['2021/12/04 11:35', '\n既に入力済み：「堀見」「井谷」「石塚」「椋下」\n入力完了：なし\nエラー：なし']], 'auto_mail_check': [['2021/12/28 21:18', None], ['2021/12/04 12:14', None], ['2021/12/04 11:42', None], ['2021/12/04 11:36', None], ['2021/12/04 11:31', None]], 'auto_manga_check': [['2021/12/04 12:14', '']]}
2021-12-29 11:41:40,233: INFO: 実行：auto_bt_check.py
2021-12-29 11:42:49,567: DEBUG: [['2021/12/29 11:42', None]]
2021-12-29 11:42:49,567: DEBUG: [['2021/12/29 11:42', None], ['2021/12/28 21:17', None], ['2021/12/28 21:16', None], ['2021/12/04 12:13', '\n既に入力済み：「堀見」「井谷」「石塚」「椋下」\n入力完了：なし\nエラー：なし'], ['2021/12/04 11:41', 'NameError: name \'es\' is not defined [auto_bt_check/app.py][line:101]\n\nTraceback (most recent call last):\n  File "C:\\Users\\kizuk\\Desktop\\git\\python-garage\\autorun_manager\\..\\auto_bt_check\\app.py", line 101, in run\n    status = health_check(name,list)\n  File "C:\\Users\\kizuk\\Desktop\\git\\python-garage\\autorun_manager\\..\\auto_bt_check\\app.py", line 50, in health_check\n    es.write_all([[\'input#username\',true_list[0]],[\'input#password\',true_list[1]]])\nNameError: name \'es\' is not defined\n'], ['2021/12/04 11:35', '\n既に入力済み：「堀見」「井谷」「石塚」「椋下」\n入力完了：なし\nエラー：なし']]
2021-12-29 11:42:49,567: DEBUG: {'auto_bt_check': [['2021/12/29 11:42', None], ['2021/12/28 21:17', None], ['2021/12/28 21:16', None], ['2021/12/04 12:13', '\n既に入力済み：「堀見」「井谷」「石塚」「椋下」\n入力完了：なし\nエラー：なし'], ['2021/12/04 11:41', 'NameError: name \'es\' is not defined [auto_bt_check/app.py][line:101]\n\nTraceback (most recent call last):\n  File "C:\\Users\\kizuk\\Desktop\\git\\python-garage\\autorun_manager\\..\\auto_bt_check\\app.py", line 101, in run\n    status = health_check(name,list)\n  File "C:\\Users\\kizuk\\Desktop\\git\\python-garage\\autorun_manager\\..\\auto_bt_check\\app.py", line 50, in health_check\n    es.write_all([[\'input#username\',true_list[0]],[\'input#password\',true_list[1]]])\nNameError: name \'es\' is not defined\n']], 'auto_mail_check': [['2021/12/28 21:18', None], ['2021/12/04 12:14', None], ['2021/12/04 11:42', None], ['2021/12/04 11:36', None], ['2021/12/04 11:31', None]], 'auto_manga_check': [['2021/12/04 12:14', '']]}
2021-12-29 11:42:49,567: INFO: ---------- 関数.run_app 実行 ----------
2021-12-29 11:42:49,567: INFO: [実行元]C:\Users\kizuk\Desktop\git\python-garage\autorun_manager\app.py 224行目 <module>
2021-12-29 11:42:49,567: INFO: [実行元]C:\Users\kizuk\Desktop\git\python-garage\autorun_manager\..\modules\easylogger.py 76行目 _decoration_func
2021-12-29 11:42:49,583: DEBUG: {'auto_bt_check': [['2021/12/29 11:42', None], ['2021/12/28 21:17', None], ['2021/12/28 21:16', None], ['2021/12/04 12:13', '\n既に入力済み：「堀見」「井谷」「石塚」「椋下」\n入力完了：なし\nエラー：なし'], ['2021/12/04 11:41', 'NameError: name \'es\' is not defined [auto_bt_check/app.py][line:101]\n\nTraceback (most recent call last):\n  File "C:\\Users\\kizuk\\Desktop\\git\\python-garage\\autorun_manager\\..\\auto_bt_check\\app.py", line 101, in run\n    status = health_check(name,list)\n  File "C:\\Users\\kizuk\\Desktop\\git\\python-garage\\autorun_manager\\..\\auto_bt_check\\app.py", line 50, in health_check\n    es.write_all([[\'input#username\',true_list[0]],[\'input#password\',true_list[1]]])\nNameError: name \'es\' is not defined\n']], 'auto_mail_check': [['2021/12/28 21:18', None], ['2021/12/04 12:14', None], ['2021/12/04 11:42', None], ['2021/12/04 11:36', None], ['2021/12/04 11:31', None]], 'auto_manga_check': [['2021/12/04 12:14', '']]}
2021-12-29 11:42:49,583: INFO: 実行：auto_bt_check.py
2021-12-29 11:43:16,515: DEBUG: [['2021/12/29 11:43', None]]
2021-12-29 11:43:16,515: DEBUG: [['2021/12/29 11:43', None], ['2021/12/29 11:42', None], ['2021/12/28 21:17', None], ['2021/12/28 21:16', None], ['2021/12/04 12:13', '\n既に入力済み：「堀見」「井谷」「石塚」「椋下」\n入力完了：なし\nエラー：なし'], ['2021/12/04 11:41', 'NameError: name \'es\' is not defined [auto_bt_check/app.py][line:101]\n\nTraceback (most recent call last):\n  File "C:\\Users\\kizuk\\Desktop\\git\\python-garage\\autorun_manager\\..\\auto_bt_check\\app.py", line 101, in run\n    status = health_check(name,list)\n  File "C:\\Users\\kizuk\\Desktop\\git\\python-garage\\autorun_manager\\..\\auto_bt_check\\app.py", line 50, in health_check\n    es.write_all([[\'input#username\',true_list[0]],[\'input#password\',true_list[1]]])\nNameError: name \'es\' is not defined\n']]
2021-12-29 11:43:16,515: DEBUG: {'auto_bt_check': [['2021/12/29 11:43', None], ['2021/12/29 11:42', None], ['2021/12/28 21:17', None], ['2021/12/28 21:16', None], ['2021/12/04 12:13', '\n既に入力済み：「堀見」「井谷」「石塚」「椋下」\n入力完了：なし\nエラー：なし']], 'auto_mail_check': [['2021/12/28 21:18', None], ['2021/12/04 12:14', None], ['2021/12/04 11:42', None], ['2021/12/04 11:36', None], ['2021/12/04 11:31', None]], 'auto_manga_check': [['2021/12/04 12:14', '']]}
2021-12-29 11:43:16,515: INFO: ---------- 関数.run_app 実行 ----------
2021-12-29 11:43:16,515: INFO: [実行元]C:\Users\kizuk\Desktop\git\python-garage\autorun_manager\app.py 224行目 <module>
2021-12-29 11:43:16,515: INFO: [実行元]C:\Users\kizuk\Desktop\git\python-garage\autorun_manager\..\modules\easylogger.py 76行目 _decoration_func
2021-12-29 11:43:16,515: DEBUG: {'auto_bt_check': [['2021/12/29 11:43', None], ['2021/12/29 11:42', None], ['2021/12/28 21:17', None], ['2021/12/28 21:16', None], ['2021/12/04 12:13', '\n既に入力済み：「堀見」「井谷」「石塚」「椋下」\n入力完了：なし\nエラー：なし']], 'auto_mail_check': [['2021/12/28 21:18', None], ['2021/12/04 12:14', None], ['2021/12/04 11:42', None], ['2021/12/04 11:36', None], ['2021/12/04 11:31', None]], 'auto_manga_check': [['2021/12/04 12:14', '']]}
2021-12-29 11:43:17,793: INFO: 実行：auto_mail_check.py
2021-12-29 11:44:09,945: DEBUG: [['2021/12/29 11:44', None]]
2021-12-29 11:44:09,945: DEBUG: [['2021/12/29 11:44', None], ['2021/12/28 21:18', None], ['2021/12/04 12:14', None], ['2021/12/04 11:42', None], ['2021/12/04 11:36', None], ['2021/12/04 11:31', None]]
2021-12-29 11:44:09,946: DEBUG: {'auto_bt_check': [['2021/12/29 11:43', None], ['2021/12/29 11:42', None], ['2021/12/28 21:17', None], ['2021/12/28 21:16', None], ['2021/12/04 12:13', '\n既に入力済み：「堀見」「井谷」「石塚」「椋下」\n入力完了：なし\nエラー：なし']], 'auto_mail_check': [['2021/12/29 11:44', None], ['2021/12/28 21:18', None], ['2021/12/04 12:14', None], ['2021/12/04 11:42', None], ['2021/12/04 11:36', None]], 'auto_manga_check': [['2021/12/04 12:14', '']]}
2021-12-29 11:44:09,950: INFO: ---------- 関数.run_app 実行 ----------
2021-12-29 11:44:09,953: INFO: [実行元]C:\Users\kizuk\Desktop\git\python-garage\autorun_manager\app.py 224行目 <module>
2021-12-29 11:44:09,954: INFO: [実行元]C:\Users\kizuk\Desktop\git\python-garage\autorun_manager\..\modules\easylogger.py 76行目 _decoration_func
2021-12-29 11:44:09,974: DEBUG: {'auto_bt_check': [['2021/12/29 11:43', None], ['2021/12/29 11:42', None], ['2021/12/28 21:17', None], ['2021/12/28 21:16', None], ['2021/12/04 12:13', '\n既に入力済み：「堀見」「井谷」「石塚」「椋下」\n入力完了：なし\nエラー：なし']], 'auto_mail_check': [['2021/12/29 11:44', None], ['2021/12/28 21:18', None], ['2021/12/04 12:14', None], ['2021/12/04 11:42', None], ['2021/12/04 11:36', None]], 'auto_manga_check': [['2021/12/04 12:14', '']]}
2021-12-29 11:44:09,975: INFO: 実行：auto_mail_check.py
2021-12-29 11:44:18,139: ERROR: urllib3.exceptions.MaxRetryError: HTTPConnectionPool(host='127.0.0.1', port=63616): Max retries exceeded with url: /session/5c9fe3684c3917d243337f91eddf910f/url (Caused by NewConnectionError('<urllib3.connection.HTTPConnection object at 0x01382538>: Failed to establish a new connection: [WinError 10061] 対象のコンピューターによって拒否されたため、接続できませんでした。')) [autorun_manager/app.py][line:158]

Traceback (most recent call last):
  File "C:\Users\kizuk\AppData\Local\Programs\Python\Python38-32\lib\site-packages\urllib3\connection.py", line 159, in _new_conn
    conn = connection.create_connection(
  File "C:\Users\kizuk\AppData\Local\Programs\Python\Python38-32\lib\site-packages\urllib3\util\connection.py", line 84, in create_connection
    raise err
  File "C:\Users\kizuk\AppData\Local\Programs\Python\Python38-32\lib\site-packages\urllib3\util\connection.py", line 74, in create_connection
    sock.connect(sa)
ConnectionRefusedError: [WinError 10061] 対象のコンピューターによって拒否されたため、接続できませんでした。

During handling of the above exception, another exception occurred:

Traceback (most recent call last):
  File "C:\Users\kizuk\AppData\Local\Programs\Python\Python38-32\lib\site-packages\urllib3\connectionpool.py", line 670, in urlopen
    httplib_response = self._make_request(
  File "C:\Users\kizuk\AppData\Local\Programs\Python\Python38-32\lib\site-packages\urllib3\connectionpool.py", line 392, in _make_request
    conn.request(method, url, **httplib_request_kw)
  File "C:\Users\kizuk\AppData\Local\Programs\Python\Python38-32\lib\http\client.py", line 1240, in request
    self._send_request(method, url, body, headers, encode_chunked)
  File "C:\Users\kizuk\AppData\Local\Programs\Python\Python38-32\lib\http\client.py", line 1286, in _send_request
    self.endheaders(body, encode_chunked=encode_chunked)
  File "C:\Users\kizuk\AppData\Local\Programs\Python\Python38-32\lib\http\client.py", line 1235, in endheaders
    self._send_output(message_body, encode_chunked=encode_chunked)
  File "C:\Users\kizuk\AppData\Local\Programs\Python\Python38-32\lib\http\client.py", line 1006, in _send_output
    self.send(msg)
  File "C:\Users\kizuk\AppData\Local\Programs\Python\Python38-32\lib\http\client.py", line 946, in send
    self.connect()
  File "C:\Users\kizuk\AppData\Local\Programs\Python\Python38-32\lib\site-packages\urllib3\connection.py", line 187, in connect
    conn = self._new_conn()
  File "C:\Users\kizuk\AppData\Local\Programs\Python\Python38-32\lib\site-packages\urllib3\connection.py", line 171, in _new_conn
    raise NewConnectionError(
urllib3.exceptions.NewConnectionError: <urllib3.connection.HTTPConnection object at 0x01382538>: Failed to establish a new connection: [WinError 10061] 対象のコンピューターによって拒否されたため、接続できませんでした。

During handling of the above exception, another exception occurred:

Traceback (most recent call last):
  File "C:\Users\kizuk\Desktop\git\python-garage\autorun_manager\app.py", line 158, in run_all_apps
    run_app(key)
  File "C:\Users\kizuk\Desktop\git\python-garage\autorun_manager\..\modules\easylogger.py", line 76, in _decoration_func
    return func(*args, **kwargs)
  File "C:\Users\kizuk\Desktop\git\python-garage\autorun_manager\app.py", line 171, in run_app
    result_text = app.run()
  File "C:\Users\kizuk\Desktop\git\python-garage\autorun_manager\..\auto_mail_check\app.py", line 113, in run
    es.get('https://webmail.jikei.ac.jp/',sleeptime=5)
  File "C:\Users\kizuk\Desktop\git\python-garage\autorun_manager\..\modules\easyselenium.py", line 56, in get
    self.driver.get(url)
  File "C:\Users\kizuk\AppData\Local\Programs\Python\Python38-32\lib\site-packages\selenium\webdriver\remote\webdriver.py", line 333, in get
    self.execute(Command.GET, {'url': url})
  File "C:\Users\kizuk\AppData\Local\Programs\Python\Python38-32\lib\site-packages\selenium\webdriver\remote\webdriver.py", line 319, in execute
    response = self.command_executor.execute(driver_command, params)
  File "C:\Users\kizuk\AppData\Local\Programs\Python\Python38-32\lib\site-packages\selenium\webdriver\remote\remote_connection.py", line 374, in execute
    return self._request(command_info[0], url, body=data)
  File "C:\Users\kizuk\AppData\Local\Programs\Python\Python38-32\lib\site-packages\selenium\webdriver\remote\remote_connection.py", line 397, in _request
    resp = self._conn.request(method, url, body=body, headers=headers)
  File "C:\Users\kizuk\AppData\Local\Programs\Python\Python38-32\lib\site-packages\urllib3\request.py", line 79, in request
    return self.request_encode_body(
  File "C:\Users\kizuk\AppData\Local\Programs\Python\Python38-32\lib\site-packages\urllib3\request.py", line 171, in request_encode_body
    return self.urlopen(method, url, **extra_kw)
  File "C:\Users\kizuk\AppData\Local\Programs\Python\Python38-32\lib\site-packages\urllib3\poolmanager.py", line 336, in urlopen
    response = conn.urlopen(method, u.request_uri, **kw)
  File "C:\Users\kizuk\AppData\Local\Programs\Python\Python38-32\lib\site-packages\urllib3\connectionpool.py", line 752, in urlopen
    return self.urlopen(
  File "C:\Users\kizuk\AppData\Local\Programs\Python\Python38-32\lib\site-packages\urllib3\connectionpool.py", line 752, in urlopen
    return self.urlopen(
  File "C:\Users\kizuk\AppData\Local\Programs\Python\Python38-32\lib\site-packages\urllib3\connectionpool.py", line 752, in urlopen
    return self.urlopen(
  File "C:\Users\kizuk\AppData\Local\Programs\Python\Python38-32\lib\site-packages\urllib3\connectionpool.py", line 724, in urlopen
    retries = retries.increment(
  File "C:\Users\kizuk\AppData\Local\Programs\Python\Python38-32\lib\site-packages\urllib3\util\retry.py", line 439, in increment
    raise MaxRetryError(_pool, url, error or ResponseError(cause))
urllib3.exceptions.MaxRetryError: HTTPConnectionPool(host='127.0.0.1', port=63616): Max retries exceeded with url: /session/5c9fe3684c3917d243337f91eddf910f/url (Caused by NewConnectionError('<urllib3.connection.HTTPConnection object at 0x01382538>: Failed to establish a new connection: [WinError 10061] 対象のコンピューターによって拒否されたため、接続できませんでした。'))

